Workbook

Sheet Read me
A1: EMEA Sales Operations Toolkit (demo workbook)
A2: All accounts, people and figures are fictional and generated for demonstration.
A4: Opportunities: raw CRM export with formula-driven data quality checks (columns V to AB).
A5: Pipeline summary: stage x region pivot built with SUMIFS so it updates with the data.
A6: Data quality: completeness score per region, target 95%.
A7: Forecast: forecast vs actual by quarter with accuracy %.
A8: Tradeshows: post-event funnel and cost per qualified lead.

Sheet Opportunities
A1: opportunity_id | B1: account | C1: region | D1: country | E1: owner | F1: vertical | G1: product_family | H1: stage | I1: probability | J1: annual_units | K1: asp_usd | L1: project_life_years | M1: annual_value_usd | N1: lifetime_value_usd | O1: weighted_value_usd | P1: created_date | Q1: expected_close | R1: days_since_update | S1: next_action | T1: source | U1: loss_reason | V1: chk_next_action | W1: chk_volume | X1: chk_vertical | Y1: chk_close_past | Z1: chk_stale | AA1: chk_duplicate | AB1: issues
A2: OPP-26000 | B2: Sava Electronics | C2: UK & Ireland | D2: United Kingdom | E2: R. Patel | F2: Industrial IoT | G2: LTE Cat 1 bis | H2: Pilot | I2: 0.85 | J2: 20000 | K2: 10.24 | L2: 3 | M2: 204800 | N2: 614400 | O2: 522240 | P2: 2025-12-31 | Q2: 2026-11-30 | R2: 79 | S2: Certification plan | T2: Website | V2: =IF(S2="",1,0) | W2: =IF(J2="",1,0) | X2: =IF(F2="",1,0) | Y2: =IF(AND(AND(H2<>"Mass production",H2<>"Lost"),DATEVALUE(Q2)<DATE(2026,10,20)),1,0) | Z2: =IF(AND(AND(H2<>"Mass production",H2<>"Lost"),R2>30),1,0) | AA2: =IF(COUNTIFS($G$2:$G$247,G2,$F$2:$F$247,F2,$J$2:$J$247,J2,$K$2:$K$247,K2)>1,1,0) | AB2: =SUM(V2:AA2)
A3: OPP-26001 | B3: Nordwind Connect | C3: UK & Ireland | D3: United Kingdom | E3: R. Patel | F3: Healthcare | G3: Wi-Fi / Bluetooth | H3: Mass production | I3: 1 | J3: 2000 | K3: 3.3 | L3: 3 | M3: 6600 | N3: 19800 | O3: 19800 | P3: 2025-08-18 | Q3: 2026-06-02 | R3: 13 | S3: Send samples | T3: Direct | V3: =IF(S3="",1,0) | W3: =IF(J3="",1,0) | X3: =IF(F3="",1,0) | Y3: =IF(AND(AND(H3<>"Mass production",H3<>"Lost"),DATEVALUE(Q3)<DATE(2026,10,20)),1,0) | Z3: =IF(AND(AND(H3<>"Mass production",H3<>"Lost"),R3>30),1,0) | AA3: =IF(COUNTIFS($G$2:$G$247,G3,$F$2:$F$247,F3,$J$2:$J$247,J3,$K$2:$K$247,K3)>1,1,0) | AB3: =SUM(V3:AA3)
A4: OPP-26002 | B4: Sava Electronics | C4: UK & Ireland | D4: United Kingdom | E4: S. Clarke | F4: POS & payments | G4: LTE Cat 1 bis | H4: Design-win | I4: 0.7 | J4: 80000 | K4: 7.63 | L4: 4 | M4: 610400 | N4: 2441600 | O4: 1709120 | P4: 2025-10-12 | Q4: 2027-02-17 | R4: 80 | T4: Tradeshow | V4: =IF(S4="",1,0) | W4: =IF(J4="",1,0) | X4: =IF(F4="",1,0) | Y4: =IF(AND(AND(H4<>"Mass production",H4<>"Lost"),DATEVALUE(Q4)<DATE(2026,10,20)),1,0) | Z4: =IF(AND(AND(H4<>"Mass production",H4<>"Lost"),R4>30),1,0) | AA4: =IF(COUNTIFS($G$2:$G$247,G4,$F$2:$F$247,F4,$J$2:$J$247,J4,$K$2:$K$247,K4)>1,1,0) | AB4: =SUM(V4:AA4)
A5: OPP-26003 | B5: Ferro Metering | C5: Middle East & Africa | D5: Israel | E5: Y. Cohen | F5: POS & payments | G5: Smart module | H5: Design-win | I5: 0.7 | J5: 8000 | K5: 81.85 | L5: 3 | M5: 654800 | N5: 1964400 | O5: 1375080 | P5: 2025-07-16 | Q5: 2026-10-15 | R5: 10 | S5: Pilot build follow-up | T5: Tradeshow | V5: =IF(S5="",1,0) | W5: =IF(J5="",1,0) | X5: =IF(F5="",1,0) | Y5: =IF(AND(AND(H5<>"Mass production",H5<>"Lost"),DATEVALUE(Q5)<DATE(2026,10,20)),1,0) | Z5: =IF(AND(AND(H5<>"Mass production",H5<>"Lost"),R5>30),1,0) | AA5: =IF(COUNTIFS($G$2:$G$247,G5,$F$2:$F$247,F5,$J$2:$J$247,J5,$K$2:$K$247,K5)>1,1,0) | AB5: =SUM(V5:AA5)
A6: OPP-26004 | B6: Morava Systems | C6: France & Benelux | D6: Netherlands | E6: B. de Vries | F6: Healthcare | G6: 5G eMBB | H6: Sample / Evaluation | I6: 0.2 | J6: 20000 | K6: 95.55 | L6: 3 | M6: 1911000 | N6: 5733000 | O6: 1146600 | P6: 2025-02-25 | Q6: 2027-02-11 | R6: 6 | S6: Price negotiation | T6: Distributor | V6: =IF(S6="",1,0) | W6: =IF(J6="",1,0) | X6: =IF(F6="",1,0) | Y6: =IF(AND(AND(H6<>"Mass production",H6<>"Lost"),DATEVALUE(Q6)<DATE(2026,10,20)),1,0) | Z6: =IF(AND(AND(H6<>"Mass production",H6<>"Lost"),R6>30),1,0) | AA6: =IF(COUNTIFS($G$2:$G$247,G6,$F$2:$F$247,F6,$J$2:$J$247,J6,$K$2:$K$247,K6)>1,1,0) | AB6: =SUM(V6:AA6)
A7: OPP-26005 | B7: Stellar Devices | C7: UK & Ireland | D7: United Kingdom | E7: S. Clarke | F7: POS & payments | G7: Wi-Fi / Bluetooth | H7: Design-in | I7: 0.4 | J7: 3000 | K7: 5.08 | L7: 3 | M7: 15240 | N7: 45720 | O7: 18288 | P7: 2025-04-21 | Q7: 2026-10-05 | R7: 25 | S7: Certification plan | T7: Website | V7: =IF(S7="",1,0) | W7: =IF(J7="",1,0) | X7: =IF(F7="",1,0) | Y7: =IF(AND(AND(H7<>"Mass production",H7<>"Lost"),DATEVALUE(Q7)<DATE(2026,10,20)),1,0) | Z7: =IF(AND(AND(H7<>"Mass production",H7<>"Lost"),R7>30),1,0) | AA7: =IF(COUNTIFS($G$2:$G$247,G7,$F$2:$F$247,F7,$J$2:$J$247,J7,$K$2:$K$247,K7)>1,1,0) | AB7: =SUM(V7:AA7)
A8: OPP-26006 | B8: Atlas Industrial | C8: France & Benelux | D8: Belgium | E8: C. Martin | G8: GNSS | H8: Lost | I8: 0 | J8: 3000 | K8: 8.17 | L8: 4 | M8: 24510 | N8: 98040 | O8: 0 | P8: 2025-08-02 | Q8: 2026-09-20 | R8: 11 | S8: Technical review call | T8: Tradeshow | U8: Competitor module | V8: =IF(S8="",1,0) | W8: =IF(J8="",1,0) | X8: =IF(F8="",1,0) | Y8: =IF(AND(AND(H8<>"Mass production",H8<>"Lost"),DATEVALUE(Q8)<DATE(2026,10,20)),1,0) | Z8: =IF(AND(AND(H8<>"Mass production",H8<>"Lost"),R8>30),1,0) | AA8: =IF(COUNTIFS($G$2:$G$247,G8,$F$2:$F$247,F8,$J$2:$J$247,J8,$K$2:$K$247,K8)>1,1,0) | AB8: =SUM(V8:AA8)
A9: OPP-26007 | B9: Morava Systems | C9: France & Benelux | D9: Netherlands | E9: B. de Vries | F9: Telematics | G9: 5G RedCap | H9: Design-in | I9: 0.4 | J9: 3000 | K9: 51.38 | L9: 4 | M9: 154140 | N9: 616560 | O9: 246624 | P9: 2026-05-17 | Q9: 2027-05-05 | R9: 25 | S9: Quote revision | T9: Tradeshow | V9: =IF(S9="",1,0) | W9: =IF(J9="",1,0) | X9: =IF(F9="",1,0) | Y9: =IF(AND(AND(H9<>"Mass production",H9<>"Lost"),DATEVALUE(Q9)<DATE(2026,10,20)),1,0) | Z9: =IF(AND(AND(H9<>"Mass production",H9<>"Lost"),R9>30),1,0) | AA9: =IF(COUNTIFS($G$2:$G$247,G9,$F$2:$F$247,F9,$J$2:$J$247,J9,$K$2:$K$247,K9)>1,1,0) | AB9: =SUM(V9:AA9)
A10: OPP-26008 | B10: Rhenus Tracking | C10: UK & Ireland | D10: Ireland | E10: R. Patel | F10: Healthcare | G10: Wi-Fi / Bluetooth | H10: Pilot | I10: 0.85 | J10: 50000 | K10: 4.73 | L10: 4 | M10: 236500 | N10: 946000 | O10: 804100 | P10: 2026-01-29 | Q10: 2027-01-28 | R10: 7 | S10: Technical review call | T10: Direct | V10: =IF(S10="",1,0) | W10: =IF(J10="",1,0) | X10: =IF(F10="",1,0) | Y10: =IF(AND(AND(H10<>"Mass production",H10<>"Lost"),DATEVALUE(Q10)<DATE(2026,10,20)),1,0) | Z10: =IF(AND(AND(H10<>"Mass production",H10<>"Lost"),R10>30),1,0) | AA10: =IF(COUNTIFS($G$2:$G$247,G10,$F$2:$F$247,F10,$J$2:$J$247,J10,$K$2:$K$247,K10)>1,1,0) | AB10: =SUM(V10:AA10)
A11: OPP-26009 | B11: Corvid Health | C11: DACH | D11: Germany | E11: L. Hoffmann | F11: Smart metering | G11: 5G eMBB | H11: Qualified | I11: 0.1 | J11: 20000 | K11: 88.53 | L11: 3 | M11: 1770600 | N11: 5311800 | O11: 531180 | P11: 2025-03-24 | Q11: 2027-05-06 | R11: 57 | S11: Design review | T11: Distributor | V11: =IF(S11="",1,0) | W11: =IF(J11="",1,0) | X11: =IF(F11="",1,0) | Y11: =IF(AND(AND(H11<>"Mass production",H11<>"Lost"),DATEVALUE(Q11)<DATE(2026,10,20)),1,0) | Z11: =IF(AND(AND(H11<>"Mass production",H11<>"Lost"),R11>30),1,0) | AA11: =IF(COUNTIFS($G$2:$G$247,G11,$F$2:$F$247,F11,$J$2:$J$247,J11,$K$2:$K$247,K11)>1,1,0) | AB11: =SUM(V11:AA11)
A12: OPP-26010 | B12: Orbis Systems | C12: France & Benelux | D12: Belgium | E12: C. Martin | F12: Smart home & security | G12: Wi-Fi / Bluetooth | H12: Pilot | I12: 0.85 | J12: 20000 | K12: 5.62 | L12: 5 | M12: 112400 | N12: 562000 | O12: 477700 | P12: 2025-03-20 | Q12: 2026-12-31 | R12: 7 | S12: Forecast confirmation | T12: Tradeshow | V12: =IF(S12="",1,0) | W12: =IF(J12="",1,0) | X12: =IF(F12="",1,0) | Y12: =IF(AND(AND(H12<>"Mass production",H12<>"Lost"),DATEVALUE(Q12)<DATE(2026,10,20)),1,0) | Z12: =IF(AND(AND(H12<>"Mass production",H12<>"Lost"),R12>30),1,0) | AA12: =IF(COUNTIFS($G$2:$G$247,G12,$F$2:$F$247,F12,$J$2:$J$247,J12,$K$2:$K$247,K12)>1,1,0) | AB12: =SUM(V12:AA12)
A13: OPP-26011 | B13: Zenit Telematics | C13: UK & Ireland | D13: Ireland | E13: S. Clarke | F13: Telematics | G13: LTE-M / NB-IoT | H13: Qualified | I13: 0.1 | J13: 80000 | K13: 8.26 | L13: 5 | M13: 660800 | N13: 3304000 | O13: 330400 | P13: 2026-09-03 | Q13: 2027-03-30 | R13: 15 | S13: Quote revision | T13: Direct | V13: =IF(S13="",1,0) | W13: =IF(J13="",1,0) | X13: =IF(F13="",1,0) | Y13: =IF(AND(AND(H13<>"Mass production",H13<>"Lost"),DATEVALUE(Q13)<DATE(2026,10,20)),1,0) | Z13: =IF(AND(AND(H13<>"Mass production",H13<>"Lost"),R13>30),1,0) | AA13: =IF(COUNTIFS($G$2:$G$247,G13,$F$2:$F$247,F13,$J$2:$J$247,J13,$K$2:$K$247,K13)>1,1,0) | AB13: =SUM(V13:AA13)
A14: OPP-26012 | B14: Orbis Devices | C14: Middle East & Africa | D14: UAE | E14: Y. Cohen | F14: Healthcare | G14: LTE Cat 1 bis | H14: Design-in | I14: 0.4 | J14: 20000 | K14: 10.16 | L14: 3 | M14: 203200 | N14: 609600 | O14: 243840 | P14: 2025-07-26 | Q14: 2027-01-17 | R14: 13 | S14: Certification plan | T14: Tradeshow | V14: =IF(S14="",1,0) | W14: =IF(J14="",1,0) | X14: =IF(F14="",1,0) | Y14: =IF(AND(AND(H14<>"Mass production",H14<>"Lost"),DATEVALUE(Q14)<DATE(2026,10,20)),1,0) | Z14: =IF(AND(AND(H14<>"Mass production",H14<>"Lost"),R14>30),1,0) | AA14: =IF(COUNTIFS($G$2:$G$247,G14,$F$2:$F$247,F14,$J$2:$J$247,J14,$K$2:$K$247,K14)>1,1,0) | AB14: =SUM(V14:AA14)
A15: OPP-26013 | B15: Lumen Connect | C15: DACH | D15: Austria | E15: J. Weber | G15: 5G RedCap | H15: Lead | I15: 0.05 | J15: 8000 | K15: 60.79 | L15: 2 | M15: 486320 | N15: 972640 | O15: 48632 | P15: 2026-04-27 | Q15: 2027-01-10 | R15: 2 | S15: Pilot build follow-up | T15: Tradeshow | V15: =IF(S15="",1,0) | W15: =IF(J15="",1,0) | X15: =IF(F15="",1,0) | Y15: =IF(AND(AND(H15<>"Mass production",H15<>"Lost"),DATEVALUE(Q15)<DATE(2026,10,20)),1,0) | Z15: =IF(AND(AND(H15<>"Mass production",H15<>"Lost"),R15>30),1,0) | AA15: =IF(COUNTIFS($G$2:$G$247,G15,$F$2:$F$247,F15,$J$2:$J$247,J15,$K$2:$K$247,K15)>1,1,0) | AB15: =SUM(V15:AA15)
A16: OPP-26014 | B16: Baltix Telematics | C16: DACH | D16: Germany | E16: L. Hoffmann | F16: Smart home & security | G16: Smart module | H16: Lost | I16: 0 | K16: 50.73 | L16: 3 | M16: 0 | N16: 0 | O16: 0 | P16: 2026-06-12 | Q16: 2026-10-19 | R16: 24 | S16: Certification plan | T16: Direct | U16: Competitor module | V16: =IF(S16="",1,0) | W16: =IF(J16="",1,0) | X16: =IF(F16="",1,0) | Y16: =IF(AND(AND(H16<>"Mass production",H16<>"Lost"),DATEVALUE(Q16)<DATE(2026,10,20)),1,0) | Z16: =IF(AND(AND(H16<>"Mass production",H16<>"Lost"),R16>30),1,0) | AA16: =IF(COUNTIFS($G$2:$G$247,G16,$F$2:$F$247,F16,$J$2:$J$247,J16,$K$2:$K$247,K16)>1,1,0) | AB16: =SUM(V16:AA16)
A17: OPP-26015 | B17: Orbis Systems | C17: France & Benelux | D17: Belgium | E17: B. de Vries | F17: Smart metering | G17: GNSS | H17: Mass production | I17: 1 | K17: 7.93 | L17: 2 | M17: 0 | N17: 0 | O17: 0 | P17: 2025-10-10 | Q17: 2026-10-06 | R17: 10 | S17: Design review | T17: Website | V17: =IF(S17="",1,0) | W17: =IF(J17="",1,0) | X17: =IF(F17="",1,0) | Y17: =IF(AND(AND(H17<>"Mass production",H17<>"Lost"),DATEVALUE(Q17)<DATE(2026,10,20)),1,0) | Z17: =IF(AND(AND(H17<>"Mass production",H17<>"Lost"),R17>30),1,0) | AA17: =IF(COUNTIFS($G$2:$G$247,G17,$F$2:$F$247,F17,$J$2:$J$247,J17,$K$2:$K$247,K17)>1,1,0) | AB17: =SUM(V17:AA17)
A18: OPP-26016 | B18: Helix Health | C18: Nordics | D18: Finland | E18: E. Lindqvist | F18: Telematics | G18: Wi-Fi / Bluetooth | H18: Design-win | I18: 0.7 | J18: 5000 | K18: 4.11 | L18: 4 | M18: 20550 | N18: 82200 | O18: 57540 | P18: 2026-04-03 | Q18: 2027-06-04 | R18: 23 | S18: Design review | T18: Website | V18: =IF(S18="",1,0) | W18: =IF(J18="",1,0) | X18: =IF(F18="",1,0) | Y18: =IF(AND(AND(H18<>"Mass production",H18<>"Lost"),DATEVALUE(Q18)<DATE(2026,10,20)),1,0) | Z18: =IF(AND(AND(H18<>"Mass production",H18<>"Lost"),R18>30),1,0) | AA18: =IF(COUNTIFS($G$2:$G$247,G18,$F$2:$F$247,F18,$J$2:$J$247,J18,$K$2:$K$247,K18)>1,1,0) | AB18: =SUM(V18:AA18)
A19: OPP-26017 | B19: Arcturus Metering | C19: DACH | D19: Switzerland | E19: L. Hoffmann | F19: Asset tracking | G19: Wi-Fi / Bluetooth | H19: Mass production | I19: 1 | J19: 10000 | K19: 5.77 | L19: 4 | M19: 57700 | N19: 230800 | O19: 230800 | P19: 2026-01-24 | Q19: 2026-10-01 | R19: 9 | S19: Price negotiation | T19: Direct | V19: =IF(S19="",1,0) | W19: =IF(J19="",1,0) | X19: =IF(F19="",1,0) | Y19: =IF(AND(AND(H19<>"Mass production",H19<>"Lost"),DATEVALUE(Q19)<DATE(2026,10,20)),1,0) | Z19: =IF(AND(AND(H19<>"Mass production",H19<>"Lost"),R19>30),1,0) | AA19: =IF(COUNTIFS($G$2:$G$247,G19,$F$2:$F$247,F19,$J$2:$J$247,J19,$K$2:$K$247,K19)>1,1,0) | AB19: =SUM(V19:AA19)
A20: OPP-26018 | B20: Rhenus Health | C20: Nordics | D20: Finland | E20: E. Lindqvist | F20: Industrial IoT | G20: GNSS | H20: Sample / Evaluation | I20: 0.2 | J20: 10000 | K20: 7.36 | L20: 5 | M20: 73600 | N20: 368000 | O20: 73600 | P20: 2026-09-20 | Q20: 2027-06-01 | R20: 17 | S20: Price negotiation | T20: Tradeshow | V20: =IF(S20="",1,0) | W20: =IF(J20="",1,0) | X20: =IF(F20="",1,0) | Y20: =IF(AND(AND(H20<>"Mass production",H20<>"Lost"),DATEVALUE(Q20)<DATE(2026,10,20)),1,0) | Z20: =IF(AND(AND(H20<>"Mass production",H20<>"Lost"),R20>30),1,0) | AA20: =IF(COUNTIFS($G$2:$G$247,G20,$F$2:$F$247,F20,$J$2:$J$247,J20,$K$2:$K$247,K20)>1,1,0) | AB20: =SUM(V20:AA20)
A21: OPP-26019 | B21: Zenit Energy | C21: CEE | D21: Poland | E21: D. Jovanovic | F21: Healthcare | G21: 5G eMBB | H21: Lead | I21: 0.05 | J21: 8000 | K21: 107.24 | L21: 3 | M21: 857920 | N21: 2573760 | O21: 128688 | P21: 2025-02-12 | Q21: 2027-03-17 | R21: 85 | S21: Price negotiation | T21: Direct | V21: =IF(S21="",1,0) | W21: =IF(J21="",1,0) | X21: =IF(F21="",1,0) | Y21: =IF(AND(AND(H21<>"Mass production",H21<>"Lost"),DATEVALUE(Q21)<DATE(2026,10,20)),1,0) | Z21: =IF(AND(AND(H21<>"Mass production",H21<>"Lost"),R21>30),1,0) | AA21: =IF(COUNTIFS($G$2:$G$247,G21,$F$2:$F$247,F21,$J$2:$J$247,J21,$K$2:$K$247,K21)>1,1,0) | AB21: =SUM(V21:AA21)
A22: OPP-26020 | B22: Arcturus Telematics | C22: UK & Ireland | D22: Ireland | E22: R. Patel | F22: Automotive & C-V2X | G22: LTE Cat 1 bis | H22: Pilot | I22: 0.85 | J22: 50000 | K22: 7.92 | L22: 3 | M22: 396000 | N22: 1188000 | O22: 1009800 | P22: 2026-03-18 | Q22: 2026-12-29 | R22: 30 | S22: Certification plan | T22: Direct | V22: =IF(S22="",1,0) | W22: =IF(J22="",1,0) | X22: =IF(F22="",1,0) | Y22: =IF(AND(AND(H22<>"Mass production",H22<>"Lost"),DATEVALUE(Q22)<DATE(2026,10,20)),1,0) | Z22: =IF(AND(AND(H22<>"Mass production",H22<>"Lost"),R22>30),1,0) | AA22: =IF(COUNTIFS($G$2:$G$247,G22,$F$2:$F$247,F22,$J$2:$J$247,J22,$K$2:$K$247,K22)>1,1,0) | AB22: =SUM(V22:AA22)
A23: OPP-26021 | B23: Orbis Systems | C23: France & Benelux | D23: Belgium | E23: B. de Vries | F23: Automotive & C-V2X | G23: GNSS | H23: Lead | I23: 0.05 | J23: 2000 | K23: 4.2 | L23: 2 | M23: 8400 | N23: 16800 | O23: 840 | P23: 2025-03-13 | Q23: 2027-02-06 | R23: 112 | S23: Send samples | T23: Distributor | V23: =IF(S23="",1,0) | W23: =IF(J23="",1,0) | X23: =IF(F23="",1,0) | Y23: =IF(AND(AND(H23<>"Mass production",H23<>"Lost"),DATEVALUE(Q23)<DATE(2026,10,20)),1,0) | Z23: =IF(AND(AND(H23<>"Mass production",H23<>"Lost"),R23>30),1,0) | AA23: =IF(COUNTIFS($G$2:$G$247,G23,$F$2:$F$247,F23,$J$2:$J$247,J23,$K$2:$K$247,K23)>1,1,0) | AB23: =SUM(V23:AA23)
A24: OPP-26022 | B24: Pannon Energy | C24: DACH | D24: Switzerland | E24: J. Weber | F24: Asset tracking | G24: 5G RedCap | H24: Sample / Evaluation | I24: 0.2 | J24: 30000 | K24: 44.06 | L24: 2 | M24: 1321800 | N24: 2643600 | O24: 528720 | P24: 2026-07-26 | Q24: 2027-04-03 | R24: 17 | S24: Quote revision | T24: Website | V24: =IF(S24="",1,0) | W24: =IF(J24="",1,0) | X24: =IF(F24="",1,0) | Y24: =IF(AND(AND(H24<>"Mass production",H24<>"Lost"),DATEVALUE(Q24)<DATE(2026,10,20)),1,0) | Z24: =IF(AND(AND(H24<>"Mass production",H24<>"Lost"),R24>30),1,0) | AA24: =IF(COUNTIFS($G$2:$G$247,G24,$F$2:$F$247,F24,$J$2:$J$247,J24,$K$2:$K$247,K24)>1,1,0) | AB24: =SUM(V24:AA24)
A25: OPP-26023 | B25: Orbis Connect | C25: UK & Ireland | D25: United Kingdom | E25: R. Patel | F25: Smart home & security | G25: 5G RedCap | H25: Lost | I25: 0 | J25: 20000 | K25: 51.39 | L25: 5 | M25: 1027800 | N25: 5139000 | O25: 0 | P25: 2025-01-28 | Q25: 2025-09-20 | R25: 88 | S25: Pilot build follow-up | T25: Distributor | U25: Price | V25: =IF(S25="",1,0) | W25: =IF(J25="",1,0) | X25: =IF(F25="",1,0) | Y25: =IF(AND(AND(H25<>"Mass production",H25<>"Lost"),DATEVALUE(Q25)<DATE(2026,10,20)),1,0) | Z25: =IF(AND(AND(H25<>"Mass production",H25<>"Lost"),R25>30),1,0) | AA25: =IF(COUNTIFS($G$2:$G$247,G25,$F$2:$F$247,F25,$J$2:$J$247,J25,$K$2:$K$247,K25)>1,1,0) | AB25: =SUM(V25:AA25)
A26: OPP-26024 | B26: Ferro Systems | C26: CEE | D26: Poland | E26: K. Nowak | F26: Smart home & security | G26: Wi-Fi / Bluetooth | H26: Lead | I26: 0.05 | J26: 8000 | K26: 3.23 | L26: 3 | M26: 25840 | N26: 77520 | O26: 3876 | P26: 2026-07-09 | Q26: 2026-11-29 | R26: 3 | S26: Price negotiation | T26: Tradeshow | V26: =IF(S26="",1,0) | W26: =IF(J26="",1,0) | X26: =IF(F26="",1,0) | Y26: =IF(AND(AND(H26<>"Mass production",H26<>"Lost"),DATEVALUE(Q26)<DATE(2026,10,20)),1,0) | Z26: =IF(AND(AND(H26<>"Mass production",H26<>"Lost"),R26>30),1,0) | AA26: =IF(COUNTIFS($G$2:$G$247,G26,$F$2:$F$247,F26,$J$2:$J$247,J26,$K$2:$K$247,K26)>1,1,0) | AB26: =SUM(V26:AA26)
A27: OPP-26025 | B27: Helix Devices | C27: France & Benelux | D27: France | E27: C. Martin | F27: Asset tracking | G27: Smart module | H27: Qualified | I27: 0.1 | K27: 59.14 | L27: 2 | M27: 0 | N27: 0 | O27: 0 | P27: 2026-02-03 | Q27: 2027-01-23 | R27: 12 | S27: Pilot build follow-up | T27: Website | V27: =IF(S27="",1,0) | W27: =IF(J27="",1,0) | X27: =IF(F27="",1,0) | Y27: =IF(AND(AND(H27<>"Mass production",H27<>"Lost"),DATEVALUE(Q27)<DATE(2026,10,20)),1,0) | Z27: =IF(AND(AND(H27<>"Mass production",H27<>"Lost"),R27>30),1,0) | AA27: =IF(COUNTIFS($G$2:$G$247,G27,$F$2:$F$247,F27,$J$2:$J$247,J27,$K$2:$K$247,K27)>1,1,0) | AB27: =SUM(V27:AA27)
A28: OPP-26026 | B28: Vector Metering | C28: DACH | D28: Germany | E28: L. Hoffmann | F28: Telematics | G28: GNSS | H28: Mass production | I28: 1 | J28: 80000 | K28: 7.62 | L28: 3 | M28: 609600 | N28: 1828800 | O28: 1828800 | P28: 2025-07-08 | Q28: 2026-01-07 | R28: 11 | T28: Direct | V28: =IF(S28="",1,0) | W28: =IF(J28="",1,0) | X28: =IF(F28="",1,0) | Y28: =IF(AND(AND(H28<>"Mass production",H28<>"Lost"),DATEVALUE(Q28)<DATE(2026,10,20)),1,0) | Z28: =IF(AND(AND(H28<>"Mass production",H28<>"Lost"),R28>30),1,0) | AA28: =IF(COUNTIFS($G$2:$G$247,G28,$F$2:$F$247,F28,$J$2:$J$247,J28,$K$2:$K$247,K28)>1,1,0) | AB28: =SUM(V28:AA28)
A29: OPP-26027 | B29: Zenit Labs | C29: UK & Ireland | D29: Ireland | E29: S. Clarke | G29: GNSS | H29: Pilot | I29: 0.85 | J29: 3000 | K29: 4.88 | L29: 3 | M29: 14640 | N29: 43920 | O29: 37332 | P29: 2025-02-18 | Q29: 2026-09-20 | R29: 12 | S29: Price negotiation | T29: FAE referral | V29: =IF(S29="",1,0) | W29: =IF(J29="",1,0) | X29: =IF(F29="",1,0) | Y29: =IF(AND(AND(H29<>"Mass production",H29<>"Lost"),DATEVALUE(Q29)<DATE(2026,10,20)),1,0) | Z29: =IF(AND(AND(H29<>"Mass production",H29<>"Lost"),R29>30),1,0) | AA29: =IF(COUNTIFS($G$2:$G$247,G29,$F$2:$F$247,F29,$J$2:$J$247,J29,$K$2:$K$247,K29)>1,1,0) | AB29: =SUM(V29:AA29)
A30: OPP-26028 | B30: Vector Devices | C30: UK & Ireland | D30: United Kingdom | E30: S. Clarke | F30: Healthcare | G30: Wi-Fi / Bluetooth | H30: Design-in | I30: 0.4 | J30: 3000 | K30: 4.22 | L30: 4 | M30: 12660 | N30: 50640 | O30: 20256 | P30: 2025-10-09 | Q30: 2027-04-07 | R30: 5 | S30: Design review | T30: Tradeshow | V30: =IF(S30="",1,0) | W30: =IF(J30="",1,0) | X30: =IF(F30="",1,0) | Y30: =IF(AND(AND(H30<>"Mass production",H30<>"Lost"),DATEVALUE(Q30)<DATE(2026,10,20)),1,0) | Z30: =IF(AND(AND(H30<>"Mass production",H30<>"Lost"),R30>30),1,0) | AA30: =IF(COUNTIFS($G$2:$G$247,G30,$F$2:$F$247,F30,$J$2:$J$247,J30,$K$2:$K$247,K30)>1,1,0) | AB30: =SUM(V30:AA30)
A31: OPP-26029 | B31: Alpenlink Electronics | C31: DACH | D31: Germany | E31: J. Weber | F31: Telematics | G31: GNSS | H31: Mass production | I31: 1 | J31: 3000 | K31: 3.7 | L31: 3 | M31: 11100 | N31: 33300 | O31: 33300 | P31: 2026-01-15 | Q31: 2026-10-16 | R31: 96 | S31: Design review | T31: Direct | V31: =IF(S31="",1,0) | W31: =IF(J31="",1,0) | X31: =IF(F31="",1,0) | Y31: =IF(AND(AND(H31<>"Mass production",H31<>"Lost"),DATEVALUE(Q31)<DATE(2026,10,20)),1,0) | Z31: =IF(AND(AND(H31<>"Mass production",H31<>"Lost"),R31>30),1,0) | AA31: =IF(COUNTIFS($G$2:$G$247,G31,$F$2:$F$247,F31,$J$2:$J$247,J31,$K$2:$K$247,K31)>1,1,0) | AB31: =SUM(V31:AA31)
A32: OPP-26030 | B32: Bluecell Devices | C32: UK & Ireland | D32: United Kingdom | E32: R. Patel | F32: Automotive & C-V2X | G32: Smart module | H32: Pilot | I32: 0.85 | J32: 2000 | K32: 67.1 | L32: 3 | M32: 134200 | N32: 402600 | O32: 342210 | P32: 2025-12-31 | Q32: 2026-11-16 | R32: 87 | S32: Send samples | T32: FAE referral | V32: =IF(S32="",1,0) | W32: =IF(J32="",1,0) | X32: =IF(F32="",1,0) | Y32: =IF(AND(AND(H32<>"Mass production",H32<>"Lost"),DATEVALUE(Q32)<DATE(2026,10,20)),1,0) | Z32: =IF(AND(AND(H32<>"Mass production",H32<>"Lost"),R32>30),1,0) | AA32: =IF(COUNTIFS($G$2:$G$247,G32,$F$2:$F$247,F32,$J$2:$J$247,J32,$K$2:$K$247,K32)>1,1,0) | AB32: =SUM(V32:AA32)
A33: OPP-26031 | B33: Corvid Connect | C33: DACH | D33: Austria | E33: J. Weber | F33: Telematics | G33: LTE Cat 1 bis | H33: Pilot | I33: 0.85 | J33: 50000 | K33: 9.43 | L33: 4 | M33: 471500 | N33: 1886000 | O33: 1603100 | P33: 2026-06-27 | Q33: 2027-01-03 | R33: 90 | S33: Pilot build follow-up | T33: Distributor | V33: =IF(S33="",1,0) | W33: =IF(J33="",1,0) | X33: =IF(F33="",1,0) | Y33: =IF(AND(AND(H33<>"Mass production",H33<>"Lost"),DATEVALUE(Q33)<DATE(2026,10,20)),1,0) | Z33: =IF(AND(AND(H33<>"Mass production",H33<>"Lost"),R33>30),1,0) | AA33: =IF(COUNTIFS($G$2:$G$247,G33,$F$2:$F$247,F33,$J$2:$J$247,J33,$K$2:$K$247,K33)>1,1,0) | AB33: =SUM(V33:AA33)
A34: OPP-26032 | B34: Rhenus Devices | C34: DACH | D34: Austria | E34: L. Hoffmann | F34: Healthcare | G34: 5G eMBB | H34: Lost | I34: 0 | J34: 5000 | K34: 110.12 | L34: 4 | M34: 550600 | N34: 2202400 | O34: 0 | P34: 2026-03-19 | Q34: 2026-09-26 | R34: 14 | S34: Pilot build follow-up | T34: Website | U34: Project cancelled | V34: =IF(S34="",1,0) | W34: =IF(J34="",1,0) | X34: =IF(F34="",1,0) | Y34: =IF(AND(AND(H34<>"Mass production",H34<>"Lost"),DATEVALUE(Q34)<DATE(2026,10,20)),1,0) | Z34: =IF(AND(AND(H34<>"Mass production",H34<>"Lost"),R34>30),1,0) | AA34: =IF(COUNTIFS($G$2:$G$247,G34,$F$2:$F$247,F34,$J$2:$J$247,J34,$K$2:$K$247,K34)>1,1,0) | AB34: =SUM(V34:AA34)
A35: OPP-26033 | B35: Zenit Tracking | C35: UK & Ireland | D35: Ireland | E35: R. Patel | F35: Telematics | G35: Smart module | H35: Design-in | I35: 0.4 | J35: 5000 | K35: 69.48 | L35: 4 | M35: 347400 | N35: 1389600 | O35: 555840 | P35: 2025-03-28 | Q35: 2027-05-15 | R35: 25 | S35: Forecast confirmation | T35: Website | V35: =IF(S35="",1,0) | W35: =IF(J35="",1,0) | X35: =IF(F35="",1,0) | Y35: =IF(AND(AND(H35<>"Mass production",H35<>"Lost"),DATEVALUE(Q35)<DATE(2026,10,20)),1,0) | Z35: =IF(AND(AND(H35<>"Mass production",H35<>"Lost"),R35>30),1,0) | AA35: =IF(COUNTIFS($G$2:$G$247,G35,$F$2:$F$247,F35,$J$2:$J$247,J35,$K$2:$K$247,K35)>1,1,0) | AB35: =SUM(V35:AA35)
A36: OPP-26034 | B36: Corvid Connect | C36: DACH | D36: Austria | E36: J. Weber | F36: Telematics | G36: 5G eMBB | H36: Design-in | I36: 0.4 | J36: 20000 | K36: 132.08 | L36: 2 | M36: 2641600 | N36: 5283200 | O36: 2113280 | P36: 2025-11-09 | Q36: 2027-05-10 | R36: 80 | S36: Send samples | T36: Direct | V36: =IF(S36="",1,0) | W36: =IF(J36="",1,0) | X36: =IF(F36="",1,0) | Y36: =IF(AND(AND(H36<>"Mass production",H36<>"Lost"),DATEVALUE(Q36)<DATE(2026,10,20)),1,0) | Z36: =IF(AND(AND(H36<>"Mass production",H36<>"Lost"),R36>30),1,0) | AA36: =IF(COUNTIFS($G$2:$G$247,G36,$F$2:$F$247,F36,$J$2:$J$247,J36,$K$2:$K$247,K36)>1,1,0) | AB36: =SUM(V36:AA36)
A37: OPP-26035 | B37: Bluecell Telematics | C37: Nordics | D37: Sweden | E37: E. Lindqvist | F37: Telematics | G37: Wi-Fi / Bluetooth | H37: Mass production | I37: 1 | J37: 3000 | K37: 5.46 | L37: 5 | M37: 16380 | N37: 81900 | O37: 81900 | P37: 2025-06-20 | Q37: 2025-10-25 | R37: 114 | S37: Pilot build follow-up | T37: Direct | V37: =IF(S37="",1,0) | W37: =IF(J37="",1,0) | X37: =IF(F37="",1,0) | Y37: =IF(AND(AND(H37<>"Mass production",H37<>"Lost"),DATEVALUE(Q37)<DATE(2026,10,20)),1,0) | Z37: =IF(AND(AND(H37<>"Mass production",H37<>"Lost"),R37>30),1,0) | AA37: =IF(COUNTIFS($G$2:$G$247,G37,$F$2:$F$247,F37,$J$2:$J$247,J37,$K$2:$K$247,K37)>1,1,0) | AB37: =SUM(V37:AA37)
A38: OPP-26036 | B38: Lumen Connect | C38: DACH | D38: Austria | E38: J. Weber | F38: Industrial IoT | G38: LTE Cat 1 bis | H38: Lead | I38: 0.05 | J38: 50000 | K38: 10.48 | L38: 4 | M38: 524000 | N38: 2096000 | O38: 104800 | P38: 2025-11-10 | Q38: 2027-07-27 | R38: 11 | S38: Pilot build follow-up | T38: FAE referral | V38: =IF(S38="",1,0) | W38: =IF(J38="",1,0) | X38: =IF(F38="",1,0) | Y38: =IF(AND(AND(H38<>"Mass production",H38<>"Lost"),DATEVALUE(Q38)<DATE(2026,10,20)),1,0) | Z38: =IF(AND(AND(H38<>"Mass production",H38<>"Lost"),R38>30),1,0) | AA38: =IF(COUNTIFS($G$2:$G$247,G38,$F$2:$F$247,F38,$J$2:$J$247,J38,$K$2:$K$247,K38)>1,1,0) | AB38: =SUM(V38:AA38)
A39: OPP-26037 | B39: Zenit Labs | C39: UK & Ireland | D39: Ireland | E39: R. Patel | F39: Healthcare | G39: Wi-Fi / Bluetooth | H39: Lost | I39: 0 | J39: 3000 | K39: 4.72 | L39: 4 | M39: 14160 | N39: 56640 | O39: 0 | P39: 2026-04-13 | Q39: 2026-09-21 | R39: 16 | S39: Forecast confirmation | T39: Distributor | U39: Competitor module | V39: =IF(S39="",1,0) | W39: =IF(J39="",1,0) | X39: =IF(F39="",1,0) | Y39: =IF(AND(AND(H39<>"Mass production",H39<>"Lost"),DATEVALUE(Q39)<DATE(2026,10,20)),1,0) | Z39: =IF(AND(AND(H39<>"Mass production",H39<>"Lost"),R39>30),1,0) | AA39: =IF(COUNTIFS($G$2:$G$247,G39,$F$2:$F$247,F39,$J$2:$J$247,J39,$K$2:$K$247,K39)>1,1,0) | AB39: =SUM(V39:AA39)
A40: OPP-26038 | B40: Bluecell Labs | C40: Southern Europe | D40: Portugal | E40: A. Garcia | F40: Telematics | G40: 5G eMBB | H40: Design-win | I40: 0.7 | J40: 3000 | K40: 94.35 | L40: 5 | M40: 283050 | N40: 1415250 | O40: 990675 | P40: 2025-09-04 | Q40: 2027-01-11 | R40: 7 | S40: Pilot build follow-up | T40: Tradeshow | V40: =IF(S40="",1,0) | W40: =IF(J40="",1,0) | X40: =IF(F40="",1,0) | Y40: =IF(AND(AND(H40<>"Mass production",H40<>"Lost"),DATEVALUE(Q40)<DATE(2026,10,20)),1,0) | Z40: =IF(AND(AND(H40<>"Mass production",H40<>"Lost"),R40>30),1,0) | AA40: =IF(COUNTIFS($G$2:$G$247,G40,$F$2:$F$247,F40,$J$2:$J$247,J40,$K$2:$K$247,K40)>1,1,0) | AB40: =SUM(V40:AA40)
...

Sheet Pipeline summary
A1: Lifetime value (USD) by stage and region
A2: Stage | B2: DACH | C2: UK & Ireland | D2: France & Benelux | E2: Southern Europe | F2: Nordics | G2: CEE | H2: Middle East & Africa | I2: Total
A3: Lead | B3: =SUMIFS(Opportunities!$N$2:$N$247,Opportunities!$H$2:$H$247,$A3,Opportunities!$C$2:$C$247,B$2) | C3: =SUMIFS(Opportunities!$N$2:$N$247,Opportunities!$H$2:$H$247,$A3,Opportunities!$C$2:$C$247,C$2) | D3: =SUMIFS(Opportunities!$N$2:$N$247,Opportunities!$H$2:$H$247,$A3,Opportunities!$C$2:$C$247,D$2) | E3: =SUMIFS(Opportunities!$N$2:$N$247,Opportunities!$H$2:$H$247,$A3,Opportunities!$C$2:$C$247,E$2) | F3: =SUMIFS(Opportunities!$N$2:$N$247,Opportunities!$H$2:$H$247,$A3,Opportunities!$C$2:$C$247,F$2) | G3: =SUMIFS(Opportunities!$N$2:$N$247,Opportunities!$H$2:$H$247,$A3,Opportunities!$C$2:$C$247,G$2) | H3: =SUMIFS(Opportunities!$N$2:$N$247,Opportunities!$H$2:$H$247,$A3,Opportunities!$C$2:$C$247,H$2) | I3: =SUM(B3:H3)
A4: Qualified | B4: =SUMIFS(Opportunities!$N$2:$N$247,Opportunities!$H$2:$H$247,$A4,Opportunities!$C$2:$C$247,B$2) | C4: =SUMIFS(Opportunities!$N$2:$N$247,Opportunities!$H$2:$H$247,$A4,Opportunities!$C$2:$C$247,C$2) | D4: =SUMIFS(Opportunities!$N$2:$N$247,Opportunities!$H$2:$H$247,$A4,Opportunities!$C$2:$C$247,D$2) | E4: =SUMIFS(Opportunities!$N$2:$N$247,Opportunities!$H$2:$H$247,$A4,Opportunities!$C$2:$C$247,E$2) | F4: =SUMIFS(Opportunities!$N$2:$N$247,Opportunities!$H$2:$H$247,$A4,Opportunities!$C$2:$C$247,F$2) | G4: =SUMIFS(Opportunities!$N$2:$N$247,Opportunities!$H$2:$H$247,$A4,Opportunities!$C$2:$C$247,G$2) | H4: =SUMIFS(Opportunities!$N$2:$N$247,Opportunities!$H$2:$H$247,$A4,Opportunities!$C$2:$C$247,H$2) | I4: =SUM(B4:H4)
A5: Sample / Evaluation | B5: =SUMIFS(Opportunities!$N$2:$N$247,Opportunities!$H$2:$H$247,$A5,Opportunities!$C$2:$C$247,B$2) | C5: =SUMIFS(Opportunities!$N$2:$N$247,Opportunities!$H$2:$H$247,$A5,Opportunities!$C$2:$C$247,C$2) | D5: =SUMIFS(Opportunities!$N$2:$N$247,Opportunities!$H$2:$H$247,$A5,Opportunities!$C$2:$C$247,D$2) | E5: =SUMIFS(Opportunities!$N$2:$N$247,Opportunities!$H$2:$H$247,$A5,Opportunities!$C$2:$C$247,E$2) | F5: =SUMIFS(Opportunities!$N$2:$N$247,Opportunities!$H$2:$H$247,$A5,Opportunities!$C$2:$C$247,F$2) | G5: =SUMIFS(Opportunities!$N$2:$N$247,Opportunities!$H$2:$H$247,$A5,Opportunities!$C$2:$C$247,G$2) | H5: =SUMIFS(Opportunities!$N$2:$N$247,Opportunities!$H$2:$H$247,$A5,Opportunities!$C$2:$C$247,H$2) | I5: =SUM(B5:H5)
A6: Design-in | B6: =SUMIFS(Opportunities!$N$2:$N$247,Opportunities!$H$2:$H$247,$A6,Opportunities!$C$2:$C$247,B$2) | C6: =SUMIFS(Opportunities!$N$2:$N$247,Opportunities!$H$2:$H$247,$A6,Opportunities!$C$2:$C$247,C$2) | D6: =SUMIFS(Opportunities!$N$2:$N$247,Opportunities!$H$2:$H$247,$A6,Opportunities!$C$2:$C$247,D$2) | E6: =SUMIFS(Opportunities!$N$2:$N$247,Opportunities!$H$2:$H$247,$A6,Opportunities!$C$2:$C$247,E$2) | F6: =SUMIFS(Opportunities!$N$2:$N$247,Opportunities!$H$2:$H$247,$A6,Opportunities!$C$2:$C$247,F$2) | G6: =SUMIFS(Opportunities!$N$2:$N$247,Opportunities!$H$2:$H$247,$A6,Opportunities!$C$2:$C$247,G$2) | H6: =SUMIFS(Opportunities!$N$2:$N$247,Opportunities!$H$2:$H$247,$A6,Opportunities!$C$2:$C$247,H$2) | I6: =SUM(B6:H6)
A7: Design-win | B7: =SUMIFS(Opportunities!$N$2:$N$247,Opportunities!$H$2:$H$247,$A7,Opportunities!$C$2:$C$247,B$2) | C7: =SUMIFS(Opportunities!$N$2:$N$247,Opportunities!$H$2:$H$247,$A7,Opportunities!$C$2:$C$247,C$2) | D7: =SUMIFS(Opportunities!$N$2:$N$247,Opportunities!$H$2:$H$247,$A7,Opportunities!$C$2:$C$247,D$2) | E7: =SUMIFS(Opportunities!$N$2:$N$247,Opportunities!$H$2:$H$247,$A7,Opportunities!$C$2:$C$247,E$2) | F7: =SUMIFS(Opportunities!$N$2:$N$247,Opportunities!$H$2:$H$247,$A7,Opportunities!$C$2:$C$247,F$2) | G7: =SUMIFS(Opportunities!$N$2:$N$247,Opportunities!$H$2:$H$247,$A7,Opportunities!$C$2:$C$247,G$2) | H7: =SUMIFS(Opportunities!$N$2:$N$247,Opportunities!$H$2:$H$247,$A7,Opportunities!$C$2:$C$247,H$2) | I7: =SUM(B7:H7)
A8: Pilot | B8: =SUMIFS(Opportunities!$N$2:$N$247,Opportunities!$H$2:$H$247,$A8,Opportunities!$C$2:$C$247,B$2) | C8: =SUMIFS(Opportunities!$N$2:$N$247,Opportunities!$H$2:$H$247,$A8,Opportunities!$C$2:$C$247,C$2) | D8: =SUMIFS(Opportunities!$N$2:$N$247,Opportunities!$H$2:$H$247,$A8,Opportunities!$C$2:$C$247,D$2) | E8: =SUMIFS(Opportunities!$N$2:$N$247,Opportunities!$H$2:$H$247,$A8,Opportunities!$C$2:$C$247,E$2) | F8: =SUMIFS(Opportunities!$N$2:$N$247,Opportunities!$H$2:$H$247,$A8,Opportunities!$C$2:$C$247,F$2) | G8: =SUMIFS(Opportunities!$N$2:$N$247,Opportunities!$H$2:$H$247,$A8,Opportunities!$C$2:$C$247,G$2) | H8: =SUMIFS(Opportunities!$N$2:$N$247,Opportunities!$H$2:$H$247,$A8,Opportunities!$C$2:$C$247,H$2) | I8: =SUM(B8:H8)
A9: Mass production | B9: =SUMIFS(Opportunities!$N$2:$N$247,Opportunities!$H$2:$H$247,$A9,Opportunities!$C$2:$C$247,B$2) | C9: =SUMIFS(Opportunities!$N$2:$N$247,Opportunities!$H$2:$H$247,$A9,Opportunities!$C$2:$C$247,C$2) | D9: =SUMIFS(Opportunities!$N$2:$N$247,Opportunities!$H$2:$H$247,$A9,Opportunities!$C$2:$C$247,D$2) | E9: =SUMIFS(Opportunities!$N$2:$N$247,Opportunities!$H$2:$H$247,$A9,Opportunities!$C$2:$C$247,E$2) | F9: =SUMIFS(Opportunities!$N$2:$N$247,Opportunities!$H$2:$H$247,$A9,Opportunities!$C$2:$C$247,F$2) | G9: =SUMIFS(Opportunities!$N$2:$N$247,Opportunities!$H$2:$H$247,$A9,Opportunities!$C$2:$C$247,G$2) | H9: =SUMIFS(Opportunities!$N$2:$N$247,Opportunities!$H$2:$H$247,$A9,Opportunities!$C$2:$C$247,H$2) | I9: =SUM(B9:H9)
A10: Lost | B10: =SUMIFS(Opportunities!$N$2:$N$247,Opportunities!$H$2:$H$247,$A10,Opportunities!$C$2:$C$247,B$2) | C10: =SUMIFS(Opportunities!$N$2:$N$247,Opportunities!$H$2:$H$247,$A10,Opportunities!$C$2:$C$247,C$2) | D10: =SUMIFS(Opportunities!$N$2:$N$247,Opportunities!$H$2:$H$247,$A10,Opportunities!$C$2:$C$247,D$2) | E10: =SUMIFS(Opportunities!$N$2:$N$247,Opportunities!$H$2:$H$247,$A10,Opportunities!$C$2:$C$247,E$2) | F10: =SUMIFS(Opportunities!$N$2:$N$247,Opportunities!$H$2:$H$247,$A10,Opportunities!$C$2:$C$247,F$2) | G10: =SUMIFS(Opportunities!$N$2:$N$247,Opportunities!$H$2:$H$247,$A10,Opportunities!$C$2:$C$247,G$2) | H10: =SUMIFS(Opportunities!$N$2:$N$247,Opportunities!$H$2:$H$247,$A10,Opportunities!$C$2:$C$247,H$2) | I10: =SUM(B10:H10)

Sheet Data quality
A1: Region | B1: Records | C1: Records with issues | D1: Completeness % | E1: Stale open | F1: Close date in past | G1: Possible duplicates
A2: DACH | B2: =COUNTIF(Opportunities!$C$2:$C$247,A2) | C2: =COUNTIFS(Opportunities!$C$2:$C$247,A2,Opportunities!$AB$2:$AB$247,">0") | D2: =IF(B2=0,0,1-C2/B2) | E2: =SUMIFS(Opportunities!$Z$2:$Z$247,Opportunities!$C$2:$C$247,A2) | F2: =SUMIFS(Opportunities!$Y$2:$Y$247,Opportunities!$C$2:$C$247,A2) | G2: =SUMIFS(Opportunities!$AA$2:$AA$247,Opportunities!$C$2:$C$247,A2)
A3: UK & Ireland | B3: =COUNTIF(Opportunities!$C$2:$C$247,A3) | C3: =COUNTIFS(Opportunities!$C$2:$C$247,A3,Opportunities!$AB$2:$AB$247,">0") | D3: =IF(B3=0,0,1-C3/B3) | E3: =SUMIFS(Opportunities!$Z$2:$Z$247,Opportunities!$C$2:$C$247,A3) | F3: =SUMIFS(Opportunities!$Y$2:$Y$247,Opportunities!$C$2:$C$247,A3) | G3: =SUMIFS(Opportunities!$AA$2:$AA$247,Opportunities!$C$2:$C$247,A3)
A4: France & Benelux | B4: =COUNTIF(Opportunities!$C$2:$C$247,A4) | C4: =COUNTIFS(Opportunities!$C$2:$C$247,A4,Opportunities!$AB$2:$AB$247,">0") | D4: =IF(B4=0,0,1-C4/B4) | E4: =SUMIFS(Opportunities!$Z$2:$Z$247,Opportunities!$C$2:$C$247,A4) | F4: =SUMIFS(Opportunities!$Y$2:$Y$247,Opportunities!$C$2:$C$247,A4) | G4: =SUMIFS(Opportunities!$AA$2:$AA$247,Opportunities!$C$2:$C$247,A4)
A5: Southern Europe | B5: =COUNTIF(Opportunities!$C$2:$C$247,A5) | C5: =COUNTIFS(Opportunities!$C$2:$C$247,A5,Opportunities!$AB$2:$AB$247,">0") | D5: =IF(B5=0,0,1-C5/B5) | E5: =SUMIFS(Opportunities!$Z$2:$Z$247,Opportunities!$C$2:$C$247,A5) | F5: =SUMIFS(Opportunities!$Y$2:$Y$247,Opportunities!$C$2:$C$247,A5) | G5: =SUMIFS(Opportunities!$AA$2:$AA$247,Opportunities!$C$2:$C$247,A5)
A6: Nordics | B6: =COUNTIF(Opportunities!$C$2:$C$247,A6) | C6: =COUNTIFS(Opportunities!$C$2:$C$247,A6,Opportunities!$AB$2:$AB$247,">0") | D6: =IF(B6=0,0,1-C6/B6) | E6: =SUMIFS(Opportunities!$Z$2:$Z$247,Opportunities!$C$2:$C$247,A6) | F6: =SUMIFS(Opportunities!$Y$2:$Y$247,Opportunities!$C$2:$C$247,A6) | G6: =SUMIFS(Opportunities!$AA$2:$AA$247,Opportunities!$C$2:$C$247,A6)
A7: CEE | B7: =COUNTIF(Opportunities!$C$2:$C$247,A7) | C7: =COUNTIFS(Opportunities!$C$2:$C$247,A7,Opportunities!$AB$2:$AB$247,">0") | D7: =IF(B7=0,0,1-C7/B7) | E7: =SUMIFS(Opportunities!$Z$2:$Z$247,Opportunities!$C$2:$C$247,A7) | F7: =SUMIFS(Opportunities!$Y$2:$Y$247,Opportunities!$C$2:$C$247,A7) | G7: =SUMIFS(Opportunities!$AA$2:$AA$247,Opportunities!$C$2:$C$247,A7)
A8: Middle East & Africa | B8: =COUNTIF(Opportunities!$C$2:$C$247,A8) | C8: =COUNTIFS(Opportunities!$C$2:$C$247,A8,Opportunities!$AB$2:$AB$247,">0") | D8: =IF(B8=0,0,1-C8/B8) | E8: =SUMIFS(Opportunities!$Z$2:$Z$247,Opportunities!$C$2:$C$247,A8) | F8: =SUMIFS(Opportunities!$Y$2:$Y$247,Opportunities!$C$2:$C$247,A8) | G8: =SUMIFS(Opportunities!$AA$2:$AA$247,Opportunities!$C$2:$C$247,A8)

Sheet Forecast
A1: Quarter | B1: Forecast (M USD) | C1: Actual (M USD) | D1: Variance | E1: Accuracy %
A2: Q3 25 | B2: 8.2 | C2: 7.4 | D2: =IF(C2="","",C2-B2) | E2: =IF(C2="","",1-ABS(C2-B2)/B2)
A3: Q4 25 | B3: 8.9 | C3: 9.2 | D3: =IF(C3="","",C3-B3) | E3: =IF(C3="","",1-ABS(C3-B3)/B3)
A4: Q1 26 | B4: 9.4 | C4: 8.3 | D4: =IF(C4="","",C4-B4) | E4: =IF(C4="","",1-ABS(C4-B4)/B4)
A5: Q2 26 | B5: 9.9 | C5: 9.6 | D5: =IF(C5="","",C5-B5) | E5: =IF(C5="","",1-ABS(C5-B5)/B5)
A6: Q3 26 | B6: 10.6 | C6: 10.3 | D6: =IF(C6="","",C6-B6) | E6: =IF(C6="","",1-ABS(C6-B6)/B6)
A7: Q4 26 | B7: 11.2 | D7: =IF(C7="","",C7-B7) | E7: =IF(C7="","",1-ABS(C7-B7)/B7)

Sheet Tradeshows
A1: Event | B1: City | C1: Month | D1: Cost (EUR) | E1: Meetings | F1: Leads | G1: Qualified | H1: Opportunities | I1: Pipeline (EUR) | J1: Lead to qualified % | K1: Cost per qualified lead | L1: Pipeline per EUR
A2: Embedded World | B2: Nuremberg | C2: Mar 2026 | D2: 92000 | E2: 148 | F2: 412 | G2: 131 | H2: 38 | I2: 9400000 | J2: =IF(F2="","",G2/F2) | K2: =IF(G2="","",D2/G2) | L2: =IF(I2="","",I2/D2)
A3: MWC | B3: Barcelona | C3: Mar 2026 | D3: 118000 | E3: 96 | F3: 265 | G3: 70 | H3: 17 | I3: 6100000 | J3: =IF(F3="","",G3/F3) | K3: =IF(G3="","",D3/G3) | L3: =IF(I3="","",I3/D3)
A4: Hannover Messe | B4: Hannover | C4: Apr 2026 | D4: 54000 | E4: 61 | F4: 188 | G4: 49 | H4: 14 | I4: 3300000 | J4: =IF(F4="","",G4/F4) | K4: =IF(G4="","",D4/G4) | L4: =IF(I4="","",I4/D4)
A5: IoT Tech Expo Europe | B5: Amsterdam | C5: Sep 2026 | D5: 31000 | E5: 44 | F5: 156 | G5: 38 | H5: 9 | I5: 1700000 | J5: =IF(F5="","",G5/F5) | K5: =IF(G5="","",D5/G5) | L5: =IF(I5="","",I5/D5)
A6: electronica | B6: Munich | C6: Nov 2026 | D6: 86000 | J6: =IF(F6="","",G6/F6) | K6: =IF(G6="","",D6/G6) | L6: =IF(I6="","",I6/D6)
